Workbook

Sheet Página1
B1: PREMISSAS & DRE OPERACIONAL — Secador de Esterco (SoloBom)
C2: Unidade | D2: 2026 | E2: =D2+1 -> 2027 | F2: =E2+1 -> 2028 | G2: =F2+1 -> 2029 | H2: =G2+1 -> 2030 | I2: =H2+1 -> 2031
B3: Preço de venda (composto) | C3: R$/t | D3: 360 | E3: =D3*(1+E$4) -> 376.2 | F3: =E3*(1+F$4) -> 393.129 | G3: =F3*(1+G$4) -> 410.8198 | H3: =G3*(1+H$4) -> 429.3067 | I3: =H3*(1+I$4) -> 448.6255
B4: Inflação | C4: %aa | D4: 0.045 | E4: =D4 -> 0.045 | F4: =E4 -> 0.045 | G4: =F4 -> 0.045 | H4: =G4 -> 0.045 | I4: =H4 -> 0.045
B5: Esterco úmido — PVA (Primavera) | C5: t/dia | D5: 550 | E5: =D5 -> 550 | F5: =E5 -> 550 | G5: =F5 -> 550 | H5: =G5 -> 550 | I5: =H5 -> 550
B6: Esterco úmido — Campanha | C6: t/dia | D6: 440 | E6: =D6 -> 440 | F6: =E6 -> 440 | G6: =F6 -> 440 | H6: =G6 -> 440 | I6: =H6 -> 440
B7: Dias de operação/ano | C7: dias | D7: 365 | E7: =D7 -> 365 | F7: =E7 -> 365 | G7: =F7 -> 365 | H7: =G7 -> 365 | I7: =H7 -> 365
B8: Esterco úmido gerado | C8: t/ano | D8: =(D5+D6)*D7 -> 361350 | E8: =(E5+E6)*E7 -> 361350 | F8: =(F5+F6)*F7 -> 361350 | G8: =(G5+G6)*G7 -> 361350 | H8: =(H5+H6)*H7 -> 361350 | I8: =(I5+I6)*I7 -> 361350
B9: Umidade inicial | C9: % | D9: 0.7 | E9: =D9 -> 0.7 | F9: =E9 -> 0.7 | G9: =F9 -> 0.7 | H9: =G9 -> 0.7 | I9: =H9 -> 0.7
B10: Umidade final (pós-secador) | C10: % | D10: 0.2 | E10: =D10 -> 0.2 | F10: =E10 -> 0.2 | G10: =F10 -> 0.2 | H10: =G10 -> 0.2 | I10: =H10 -> 0.2
B11: Fator massa seca | C11: x | D11: =(1-D9)/(1-D10) -> 0.375 | E11: =(1-E9)/(1-E10) -> 0.375 | F11: =(1-F9)/(1-F10) -> 0.375 | G11: =(1-G9)/(1-G10) -> 0.375 | H11: =(1-H9)/(1-H10) -> 0.375 | I11: =(1-I9)/(1-I10) -> 0.375
B12: Composto seco produzido | C12: t/ano | D12: =D8*D11 -> 135506.25 | E12: =E8*E11 -> 135506.25 | F12: =F8*F11 -> 135506.25 | G12: =G8*G11 -> 135506.25 | H12: =H8*H11 -> 135506.25 | I12: =I8*I11 -> 135506.25
B13: Volume de venda esperado | C13: t/ano | D13: 120000 | E13: =D13 -> 120000 | F13: =E13 -> 120000 | G13: =F13 -> 120000 | H13: =G13 -> 120000 | I13: =H13 -> 120000
B14: Composto vendido | C14: t/ano | D14: =MIN(D12,D13) -> 120000 | E14: =MIN(E12,E13) -> 120000 | F14: =MIN(F12,F13) -> 120000 | G14: =MIN(G12,G13) -> 120000 | H14: =MIN(H12,H13) -> 120000 | I14: =MIN(I12,I13) -> 120000
B15: Água removida | C15: t/ano | D15: =D8-D12 -> 225843.75 | E15: =E8-E12 -> 225843.75 | F15: =F8-F12 -> 225843.75 | G15: =G8-G12 -> 225843.75 | H15: =H8-H12 -> 225843.75 | I15: =I8-I12 -> 225843.75
B17: Receita Bruta | C17: R$ | D17: =D14*D3 -> 43200000 | E17: =E14*E3 -> 45144000 | F17: =F14*F3 -> 47175480 | G17: =G14*G3 -> 49298377 | H17: =H14*H3 -> 51516804 | I17: =I14*I3 -> 53835060
B18: (−) Impostos sobre Vendas | C18: R$ | D18: =D17*D19 -> 3456000 | E18: =E17*E19 -> 3611520 | F18: =F17*F19 -> 3774038.4 | G18: =G17*G19 -> 3943870.1 | H18: =H17*H19 -> 4121344.3 | I18: =I17*I19 -> 4306804.8
B19: Carga tributária s/ vendas | C19: % | D19: 0.08 | E19: =D19 -> 0.08 | F19: =E19 -> 0.08 | G19: =F19 -> 0.08 | H19: =G19 -> 0.08 | I19: =H19 -> 0.08
B20: Receita Líquida | C20: R$ | D20: =D17-D18 -> 39744000 | E20: =E17-E18 -> 41532480 | F20: =F17-F18 -> 43401442 | G20: =G17-G18 -> 45354506 | H20: =H17-H18 -> 47395459 | I20: =I17-I18 -> 49528255
B22: Custos Variáveis | C22: R$ | D22: =D23+D25+D27+D29 -> 36188906 | E22: =E23+E25+E27+E29 -> 37817407 | F22: =F23+F25+F27+F29 -> 39519190 | G22: =G23+G25+G27+G29 -> 41297554 | H22: =H23+H25+H27+H29 -> 43155944 | I22: =I23+I25+I27+I29 -> 45097961
B23: (−) Energia (secagem/biomassa) | C23: R$ | D23: =D24*D15 -> 26423719 | E23: =E24*E15 -> 27612786 | F23: =F24*F15 -> 28855361 | G23: =G24*G15 -> 30153853 | H23: =H24*H15 -> 31510776 | I23: =I24*I15 -> 32928761
B24: Custo de energia | C24: R$/t água | D24: 117 | E24: =D24*(1+E$4) -> 122.265 | F24: =E24*(1+F$4) -> 127.76692 | G24: =F24*(1+G$4) -> 133.51644 | H24: =G24*(1+H$4) -> 139.52468 | I24: =H24*(1+I$4) -> 145.80329
B25: (−) Aditivos | C25: R$ | D25: =D26*D12 -> 4065187.5 | E25: =E26*E12 -> 4248120.9 | F25: =F26*F12 -> 4439286.4 | G25: =G26*G12 -> 4639054.3 | H25: =H26*H12 -> 4847811.7 | I25: =I26*I12 -> 5065963.2
B26: Custo de aditivos | C26: R$/t seco | D26: 30 | E26: =D26*(1+E$4) -> 31.35 | F26: =E26*(1+F$4) -> 32.76075 | G26: =F26*(1+G$4) -> 34.234984 | H26: =G26*(1+H$4) -> 35.775558 | I26: =H26*(1+I$4) -> 37.385458
B27: (−) Embalagem/ensaque | C27: R$ | D27: =D28*D14 -> 3000000 | E27: =E28*E14 -> 3135000 | F27: =F28*F14 -> 3276075 | G27: =G28*G14 -> 3423498.4 | H27: =H28*H14 -> 3577555.8 | I27: =I28*I14 -> 3738545.8
B28: Custo de embalagem | C28: R$/t vend | D28: 25 | E28: =D28*(1+E$4) -> 26.125 | F28: =E28*(1+F$4) -> 27.300625 | G28: =F28*(1+G$4) -> 28.529153 | H28: =G28*(1+H$4) -> 29.812965 | I28: =H28*(1+I$4) -> 31.154548
B29: (−) Frete | C29: R$ | D29: =D14*D30*D31 -> 2700000 | E29: =E14*E30*E31 -> 2821500 | F29: =F14*F30*F31 -> 2948467.5 | G29: =G14*G30*G31 -> 3081148.5 | H29: =H14*H30*H31 -> 3219800.2 | I29: =I14*I30*I31 -> 3364691.2
B30: Distância média de entrega | C30: km | D30: 50 | E30: =D30 -> 50 | F30: =E30 -> 50 | G30: =F30 -> 50 | H30: =G30 -> 50 | I30: =H30 -> 50
B31: Frete | C31: R$/t·km | D31: 0.45 | E31: =D31*(1+E$4) -> 0.47025 | F31: =E31*(1+F$4) -> 0.49141125 | G31: =F31*(1+G$4) -> 0.51352476 | H31: =G31*(1+H$4) -> 0.53663337 | I31: =H31*(1+I$4) -> 0.56078187
B33: Custos Fixos | C33: R$ | D33: =D34+D38 -> 2207600 | E33: =E34+E38 -> 2285360 | F33: =F34+F38 -> 2366619.2 | G33: =G34+G38 -> 2451535.1 | H33: =H34+H38 -> 2540272.1 | I33: =I34+I38 -> 2633002.4
B34: (−) Mão de obra | C34: R$ | D34: =D35*D36*12*(1+D37) -> 1728000 | E34: =E35*E36*12*(1+E37) -> 1805760 | F34: =F35*F36*12*(1+F37) -> 1887019.2 | G34: =G35*G36*12*(1+G37) -> 1971935.1 | H34: =H35*H36*12*(1+H37) -> 2060672.1 | I34: =I35*I36*12*(1+I37) -> 2153402.4
B35: Nº de operadores | C35: # | D35: 20 | E35: =D35 -> 20 | F35: =E35 -> 20 | G35: =F35 -> 20 | H35: =G35 -> 20 | I35: =H35 -> 20
B36: Salário mensal/operador | C36: R$ | D36: 4000 | E36: =D36*(1+E$4) -> 4180 | F36: =E36*(1+F$4) -> 4368.1 | G36: =F36*(1+G$4) -> 4564.6645 | H36: =G36*(1+H$4) -> 4770.0744 | I36: =H36*(1+I$4) -> 4984.7278
B37: Encargos s/ folha | C37: % | D37: 0.8 | E37: =D37 -> 0.8 | F37: =E37 -> 0.8 | G37: =F37 -> 0.8 | H37: =G37 -> 0.8 | I37: =H37 -> 0.8
B38: (−) Manutenção | C38: R$ | D38: =D39*CAPEX!$D$3 -> 479600 | E38: =E39*CAPEX!$D$3 -> 479600 | F38: =F39*CAPEX!$D$3 -> 479600 | G38: =G39*CAPEX!$D$3 -> 479600 | H38: =H39*CAPEX!$D$3 -> 479600 | I38: =I39*CAPEX!$D$3 -> 479600
B39: Manutenção (% do imobilizado) | C39: % | D39: 0.04 | E39: =D39 -> 0.04 | F39: =E39 -> 0.04 | G39: =F39 -> 0.04 | H39: =G39 -> 0.04 | I39: =H39 -> 0.04
B41: Lucro Bruto | C41: R$ | D41: =D20-D22-D33 -> 1347493.8 | E41: =E20-E22-E33 -> 1429713 | F41: =F20-F22-F33 -> 1515632.1 | G41: =G20-G22-G33 -> 1605417.5 | H41: =H20-H22-H33 -> 1699243.3 | I41: =I20-I22-I33 -> 1797291.2
B42: Margem Bruta | C42: % | D42: =D41/D20 -> 0.033904331 | E42: =E41/E20 -> 0.034423973 | F42: =F41/F20 -> 0.034921238 | G42: =G41/G20 -> 0.035397089 | H42: =H41/H20 -> 0.035852449 | I42: =I41/I20 -> 0.0362882
B44: (+) Descarte evitado | C44: R$ | D44: =D45*D8 -> 2890800 | E44: =E45*E8 -> 3020886 | F44: =F45*F8 -> 3156825.9 | G44: =G45*G8 -> 3298883 | H44: =H45*H8 -> 3447332.8 | I44: =I45*I8 -> 3602462.7
B45: Custo de descarte evitado (economia) | C45: R$/t esterco | D45: 8 | E45: =D45*(1+E$4) -> 8.36 | F45: =E45*(1+F$4) -> 8.7362 | G45: =F45*(1+G$4) -> 9.129329 | H45: =G45*(1+H$4) -> 9.5401488 | I45: =H45*(1+I$4) -> 9.9694555
...

Sheet DRE
B1: DRE — SoloBom
C2: Unidade | D2: =Página1!D2 -> 2026 | E2: =D2+1 -> 2027 | F2: =E2+1 -> 2028 | G2: =F2+1 -> 2029 | H2: =G2+1 -> 2030 | I2: =H2+1 -> 2031
B3: Receita Bruta | C3: R$ | D3: =Página1!D17 -> 43200000 | E3: =Página1!E17 -> 45144000 | F3: =Página1!F17 -> 47175480 | G3: =Página1!G17 -> 49298377 | H3: =Página1!H17 -> 51516804 | I3: =Página1!I17 -> 53835060
B4: yoy | C4: % | E4: =E3/D3-1 -> 0.045 | F4: =F3/E3-1 -> 0.045 | G4: =G3/F3-1 -> 0.045 | H4: =H3/G3-1 -> 0.045 | I4: =I3/H3-1 -> 0.045
B5: Impostos sobre Vendas | C5: R$ | D5: =Página1!D18 -> 3456000 | E5: =Página1!E18 -> 3611520 | F5: =Página1!F18 -> 3774038.4 | G5: =Página1!G18 -> 3943870.1 | H5: =Página1!H18 -> 4121344.3 | I5: =Página1!I18 -> 4306804.8
B6: Receita Líquida | C6: R$ | D6: =D3-D5 -> 39744000 | E6: =E3-E5 -> 41532480 | F6: =F3-F5 -> 43401442 | G6: =G3-G5 -> 45354506 | H6: =H3-H5 -> 47395459 | I6: =I3-I5 -> 49528255
B7: yoy | C7: % | E7: =E6/D6-1 -> 0.045 | F7: =F6/E6-1 -> 0.045 | G7: =G6/F6-1 -> 0.045 | H7: =H6/G6-1 -> 0.045 | I7: =I6/H6-1 -> 0.045
B8: Custos Variáveis | C8: R$ | D8: =Página1!D22 -> 36188906 | E8: =Página1!E22 -> 37817407 | F8: =Página1!F22 -> 39519190 | G8: =Página1!G22 -> 41297554 | H8: =Página1!H22 -> 43155944 | I8: =Página1!I22 -> 45097961
B9: Custos Fixos | C9: R$ | D9: =Página1!D33 -> 2207600 | E9: =Página1!E33 -> 2285360 | F9: =Página1!F33 -> 2366619.2 | G9: =Página1!G33 -> 2451535.1 | H9: =Página1!H33 -> 2540272.1 | I9: =Página1!I33 -> 2633002.4
B10: Lucro Bruto | C10: R$ | D10: =D6-D8-D9 -> 1347493.8 | E10: =E6-E8-E9 -> 1429713 | F10: =F6-F8-F9 -> 1515632.1 | G10: =G6-G8-G9 -> 1605417.5 | H10: =H6-H8-H9 -> 1699243.3 | I10: =I6-I8-I9 -> 1797291.2
B11: Margem Bruta | C11: % | D11: =D10/D$6 -> 0.033904331 | E11: =E10/E$6 -> 0.034423973 | F11: =F10/F$6 -> 0.034921238 | G11: =G10/G$6 -> 0.035397089 | H11: =H10/H$6 -> 0.035852449 | I11: =I10/I$6 -> 0.0362882
B12: (+) Descarte evitado | C12: R$ | D12: =Página1!D44 -> 2890800 | E12: =Página1!E44 -> 3020886 | F12: =Página1!F44 -> 3156825.9 | G12: =Página1!G44 -> 3298883 | H12: =Página1!H44 -> 3447332.8 | I12: =Página1!I44 -> 3602462.7
B13: (−) Despesas | C13: R$ | D13: =Página1!D46 -> 360000 | E13: =Página1!E46 -> 376200 | F13: =Página1!F46 -> 393129 | G13: =Página1!G46 -> 410819.8 | H13: =Página1!H46 -> 429306.7 | I13: =Página1!I46 -> 448625.5
B14: EBITDA | C14: R$ | D14: =D10+D12-D13 -> 3878293.8 | E14: =E10+E12-E13 -> 4074399 | F14: =F10+F12-F13 -> 4279328.9 | G14: =G10+G12-G13 -> 4493480.7 | H14: =H10+H12-H13 -> 4717269.4 | I14: =I10+I12-I13 -> 4951128.5
B15: Margem EBITDA | C15: % | D15: =D14/D$6 -> 0.097581868 | E15: =E14/E$6 -> 0.098101509 | F15: =F14/F$6 -> 0.098598774 | G15: =G14/G$6 -> 0.099074625 | H15: =H14/H$6 -> 0.099529985 | I15: =I14/I$6 -> 0.099965736
B16: (−) Depreciação e Amortização | C16: R$ | D16: =CAPEX!D10 -> 0 | E16: =CAPEX!E10 -> 1199000 | F16: =CAPEX!F10 -> 1199000 | G16: =CAPEX!G10 -> 1199000 | H16: =CAPEX!H10 -> 1199000 | I16: =CAPEX!I10 -> 1199000
B17: EBIT | C17: R$ | D17: =D14-D16 -> 3878293.8 | E17: =E14-E16 -> 2875399 | F17: =F14-F16 -> 3080328.9 | G17: =G14-G16 -> 3294480.7 | H17: =H14-H16 -> 3518269.4 | I17: =I14-I16 -> 3752128.5
B18: Margem EBIT | C18: % | D18: =D17/D$6 -> 0.097581868 | E18: =E17/E$6 -> 0.069232537 | F18: =F17/F$6 -> 0.070972963 | G18: =G17/G$6 -> 0.072638443 | H18: =H17/H$6 -> 0.074232203 | I18: =I17/I$6 -> 0.075757333
B19: Receita Financeira | C19: R$ | D19: =Página1!D54 -> 0 | E19: =Página1!E54 -> 0 | F19: =Página1!F54 -> 0 | G19: =Página1!G54 -> 0 | H19: =Página1!H54 -> 0 | I19: =Página1!I54 -> 0
B20: (−) Despesa Financeira | C20: R$ | D20: =Dívida!D18 -> 0 | E20: =Dívida!E18 -> 1594670 | F20: =Dívida!F18 -> 1594670 | G20: =Dívida!G18 -> 1196002.5 | H20: =Dívida!H18 -> 797335 | I20: =Dívida!I18 -> 398667.5
B21: LAIR | C21: R$ | D21: =D17+D19-D20 -> 3878293.8 | E21: =E17+E19-E20 -> 1280729 | F21: =F17+F19-F20 -> 1485658.9 | G21: =G17+G19-G20 -> 2098478.2 | H21: =H17+H19-H20 -> 2720934.4 | I21: =I17+I19-I20 -> 3353461
B22: (−) IRPJ/CSLL | C22: R$ | D22: =IF(D21>0,Página1!$D$58*D21,0) -> 1318619.9 | E22: =IF(E21>0,Página1!$D$58*E21,0) -> 435447.85 | F22: =IF(F21>0,Página1!$D$58*F21,0) -> 505124.03 | G22: =IF(G21>0,Página1!$D$58*G21,0) -> 713482.6 | H22: =IF(H21>0,Página1!$D$58*H21,0) -> 925117.68 | I22: =IF(I21>0,Página1!$D$58*I21,0) -> 1140176.7
B23: Lucro Líquido | C23: R$ | D23: =D21-D22 -> 2559673.9 | E23: =E21-E22 -> 845281.12 | F23: =F21-F22 -> 980534.89 | G23: =G21-G22 -> 1384995.6 | H23: =H21-H22 -> 1795816.7 | I23: =I21-I22 -> 2213284.2
B24: Margem de Lucro Líquido | C24: % | D24: =D23/D$6 -> 0.064404033 | E24: =E23/E$6 -> 0.020352291 | F24: =F23/F$6 -> 0.022592219 | G24: =G23/G$6 -> 0.030537112 | H24: =H23/H$6 -> 0.037890057 | I24: =I23/I$6 -> 0.044687305

Sheet CAPEX
B1: CAPEX — Planta SoloBom + Frota Logística
C2: Unidade | D2: 2026 | E2: =D2+1 -> 2027 | F2: =E2+1 -> 2028 | G2: =F2+1 -> 2029 | H2: =G2+1 -> 2030 | I2: =H2+1 -> 2031
B3: Valor Investimento (= estimativa itemizada) | C3: R$ | D3: =D21 -> 11990000
B4: Tempo Depreciação | C4: anos | D4: 10
B6: Roll-forward do Imobilizado
C7: Unidade | D7: =D2 -> 2026 | E7: =E2 -> 2027 | F7: =F2 -> 2028 | G7: =G2 -> 2029 | H7: =H2 -> 2030 | I7: =I2 -> 2031 | J7: 2031 | K7: 2032 | L7: 2033 | M7: 2034 | N7: 2035
B8: Saldo Inicial | C8: R$ | D8: 0 | E8: =D11 -> 11990000 | F8: =E11 -> 10791000 | G8: =F11 -> 9592000 | H8: =G11 -> 8393000 | I8: =H11 -> 7194000 | J8: =I11 -> 5995000 | K8: =J11 -> 4796000 | L8: =K11 -> 3597000 | ... N8: =M11 -> 1199000
B9: CAPEX | C9: R$ | D9: =D3 -> 11990000 | E9: 0 | F9: 0 | G9: 0 | H9: 0 | I9: 0 | J9: =I9 -> 0 | K9: =J9 -> 0 | L9: =K9 -> 0 | M9: =L9 -> 0 | N9: =M9 -> 0
B10: Depreciação e Amortização | C10: R$ | D10: 0 | E10: =$D$3/$D$4 -> 1199000 | F10: =$D$3/$D$4 -> 1199000 | G10: =$D$3/$D$4 -> 1199000 | H10: =$D$3/$D$4 -> 1199000 | I10: =$D$3/$D$4 -> 1199000 | J10: =I10 -> 1199000 | K10: =J10 -> 1199000 | L10: =K10 -> 1199000 | M10: =L10 -> 1199000 | N10: =M10 -> 1199000
B11: Saldo Final | C11: R$ | D11: =D8+D9-D10 -> 11990000 | E11: =E8+E9-E10 -> 10791000 | F11: =F8+F9-F10 -> 9592000 | G11: =G8+G9-G10 -> 8393000 | H11: =H8+H9-H10 -> 7194000 | I11: =I8+I9-I10 -> 5995000 | J11: =J8+J9-J10 -> 4796000 | K11: =K8+K9-K10 -> 3597000 | ... N11: =N8+N9-N10 -> 0
B13: Estimativa de CAPEX por item (implementação) | C13: Unidade | D13: R$
B14: Secador industrial (linhas a biomassa) | C14: R$ | D14: 4500000
B15: Obra civil, galpão e instalação | C15: R$ | D15: 2500000
B16: Licenças ambientais | C16: R$ | D16: 500000
B17: Equipamentos auxiliares (granulação, ensacadora) | C17: R$ | D17: 1500000
B18: Frota logística (caminhões) | C18: R$ | D18: 1400000
B19: Capital de giro inicial | C19: R$ | D19: 500000
B20: Contingência (10%) | C20: R$ | D20: =0.1*SUM(D14:D19) -> 1090000
B21: CAPEX Total (implementação) | C21: R$ | D21: =SUM(D14:D20) -> 11990000

Sheet Dívida
B1: DÍVIDA — Financiamento do Investimento
C2: Unidade | D2: 2026 | E2: =D2+1 -> 2027 | F2: =E2+1 -> 2028 | G2: =F2+1 -> 2029 | H2: =G2+1 -> 2030 | I2: =H2+1 -> 2031
B3: CAPEX | C3: R$ | D3: =CAPEX!D3 -> 11990000
B4: % Financiado | C4: % | D4: 0.7
B5: Montante Dívida | C5: R$ | D5: =D3*D4 -> 8393000
B6: Carência | C6: Anos | D6: 1
B7: Tempo de Amortização | C7: Anos | D7: 4
B8: Taxa de Juros | C8: % aa | D8: =D9+D10 -> 0.19
B9: CDI | C9: % | D9: 0.14
B10: Spread | C10: % | D10: 0.05
B11: Cronograma da Dívida
C12: Unidade | D12: =D2 -> 2026 | E12: =E2 -> 2027 | F12: =F2 -> 2028 | G12: =G2 -> 2029 | H12: =H2 -> 2030 | I12: =I2 -> 2031
B13: Dívida Inicial | C13: R$ | D13: 0 | E13: =D16 -> 8393000 | F13: =E16 -> 8393000 | G13: =F16 -> 6294750 | H13: =G16 -> 4196500 | I13: =H16 -> 2098250
B14: Captação | C14: R$ | D14: =D5 -> 8393000 | E14: 0 | F14: 0 | G14: 0 | H14: 0 | I14: 0
B15: Amortização | C15: R$ | D15: 0 | E15: 0 | F15: =$D$5/$D$7 -> 2098250 | G15: =$D$5/$D$7 -> 2098250 | H15: =$D$5/$D$7 -> 2098250 | I15: =$D$5/$D$7 -> 2098250
B16: Dívida Final | C16: R$ | D16: =D13+D14-D15 -> 8393000 | E16: =E13+E14-E15 -> 8393000 | F16: =F13+F14-F15 -> 6294750 | G16: =G13+G14-G15 -> 4196500 | H16: =H13+H14-H15 -> 2098250 | I16: =I13+I14-I15 -> 0
B18: Juros | C18: R$ | D18: 0 | E18: =$D$8*E13 -> 1594670 | F18: =$D$8*F13 -> 1594670 | G18: =$D$8*G13 -> 1196002.5 | H18: =$D$8*H13 -> 797335 | I18: =$D$8*I13 -> 398667.5

Sheet Cenários
B1: CENÁRIOS — Sensibilidade à Distância de Entrega (frete)
B2: Otimista 100 km | Razoável 200 km | Pessimista 300 km — demais premissas iguais à Página1
B3: Distância média de entrega | C3: km
B4: Otimista | C4: km | D4: 100
B5: Razoável | C5: km | D5: 200
B6: Pessimista | C6: km | D6: 300
B8: FRETE (R$/ano)
D9: =Página1!D2 -> 2026 | E9: =Página1!E2 -> 2027 | F9: =Página1!F2 -> 2028 | G9: =Página1!G2 -> 2029 | H9: =Página1!H2 -> 2030 | I9: =Página1!I2 -> 2031 | J9: Total 6 anos
B10: ="Otimista ("&$D$4&" km)" -> Otimista (100 km) | D10: =Página1!D14*$D$4*Página1!D31 -> 5400000 | E10: =Página1!E14*$D$4*Página1!E31 -> 5643000 | F10: =Página1!F14*$D$4*Página1!F31 -> 5896935 | G10: =Página1!G14*$D$4*Página1!G31 -> 6162297.1 | H10: =Página1!H14*$D$4*Página1!H31 -> 6439600.4 | I10: =Página1!I14*$D$4*Página1!I31 -> 6729382.5 | J10: =SUM(D10:I10) -> 36271215
B11: ="Razoável ("&$D$5&" km)" -> Razoável (200 km) | D11: =Página1!D14*$D$5*Página1!D31 -> 10800000 | E11: =Página1!E14*$D$5*Página1!E31 -> 11286000 | F11: =Página1!F14*$D$5*Página1!F31 -> 11793870 | G11: =Página1!G14*$D$5*Página1!G31 -> 12324594 | H11: =Página1!H14*$D$5*Página1!H31 -> 12879201 | I11: =Página1!I14*$D$5*Página1!I31 -> 13458765 | J11: =SUM(D11:I11) -> 72542430
B12: ="Pessimista ("&$D$6&" km)" -> Pessimista (300 km) | D12: =Página1!D14*$D$6*Página1!D31 -> 16200000 | E12: =Página1!E14*$D$6*Página1!E31 -> 16929000 | F12: =Página1!F14*$D$6*Página1!F31 -> 17690805 | G12: =Página1!G14*$D$6*Página1!G31 -> 18486891 | H12: =Página1!H14*$D$6*Página1!H31 -> 19318801 | I12: =Página1!I14*$D$6*Página1!I31 -> 20188147 | J12: =SUM(D12:I12) -> 1.0881364e+08
B14: EBITDA (R$/ano)
D15: =D9 -> 2026 | E15: =E9 -> 2027 | F15: =F9 -> 2028 | G15: =G9 -> 2029 | H15: =H9 -> 2030 | I15: =I9 -> 2031 | J15: Total 6 anos
B16: =B10 -> Otimista (100 km) | D16: =Página1!D$49+Página1!D$29-D10 -> 1178293.8 | E16: =Página1!E$49+Página1!E$29-E10 -> 1252899 | F16: =Página1!F$49+Página1!F$29-F10 -> 1330861.4 | G16: =Página1!G$49+Página1!G$29-G10 -> 1412332.2 | H16: =Página1!H$49+Página1!H$29-H10 -> 1497469.1 | I16: =Página1!I$49+Página1!I$29-I10 -> 1586437.2 | J16: =SUM(D16:I16) -> 8258292.7
B17: =B11 -> Razoável (200 km) | D17: =Página1!D$49+Página1!D$29-D11 -> -4221706.2 | E17: =Página1!E$49+Página1!E$29-E11 -> -4390101 | F17: =Página1!F$49+Página1!F$29-F11 -> -4566073.6 | G17: =Página1!G$49+Página1!G$29-G11 -> -4749964.9 | H17: =Página1!H$49+Página1!H$29-H11 -> -4942131.3 | I17: =Página1!I$49+Página1!I$29-I11 -> -5142945.2 | J17: =SUM(D17:I17) -> -28012922
B18: =B12 -> Pessimista (300 km) | D18: =Página1!D$49+Página1!D$29-D12 -> -9621706.2 | E18: =Página1!E$49+Página1!E$29-E12 -> -10033101 | F18: =Página1!F$49+Página1!F$29-F12 -> -10463009 | G18: =Página1!G$49+Página1!G$29-G12 -> -10912262 | H18: =Página1!H$49+Página1!H$29-H12 -> -11381732 | I18: =Página1!I$49+Página1!I$29-I12 -> -11872328 | J18: =SUM(D18:I18) -> -64284137
B20: LAIR (R$/ano)
D21: =D9 -> 2026 | E21: =E9 -> 2027 | F21: =F9 -> 2028 | G21: =G9 -> 2029 | H21: =H9 -> 2030 | I21: =I9 -> 2031 | J21: Total 6 anos
B22: =B10 -> Otimista (100 km) | D22: =D16-Página1!D$51-Página1!D$55+Página1!D$54 -> 1178293.8 | E22: =E16-Página1!E$51-Página1!E$55+Página1!E$54 -> -1540771 | F22: =F16-Página1!F$51-Página1!F$55+Página1!F$54 -> -1462808.6 | G22: =G16-Página1!G$51-Página1!G$55+Página1!G$54 -> -982670.31 | H22: =H16-Página1!H$51-Página1!H$55+Página1!H$54 -> -498865.87 | I22: =I16-Página1!I$51-Página1!I$55+Página1!I$54 -> -11230.254 | J22: =SUM(D22:I22) -> -3318052.3
B23: =B11 -> Razoável (200 km) | D23: =D17-Página1!D$51-Página1!D$55+Página1!D$54 -> -4221706.2 | E23: =E17-Página1!E$51-Página1!E$55+Página1!E$54 -> -7183771 | F23: =F17-Página1!F$51-Página1!F$55+Página1!F$54 -> -7359743.6 | G23: =G17-Página1!G$51-Página1!G$55+Página1!G$54 -> -7144967.4 | H23: =H17-Página1!H$51-Página1!H$55+Página1!H$54 -> -6938466.3 | I23: =I17-Página1!I$51-Página1!I$55+Página1!I$54 -> -6740612.7 | J23: =SUM(D23:I23) -> -39589267
B24: =B12 -> Pessimista (300 km) | D24: =D18-Página1!D$51-Página1!D$55+Página1!D$54 -> -9621706.2 | E24: =E18-Página1!E$51-Página1!E$55+Página1!E$54 -> -12826771 | F24: =F18-Página1!F$51-Página1!F$55+Página1!F$54 -> -13256679 | G24: =G18-Página1!G$51-Página1!G$55+Página1!G$54 -> -13307264 | H24: =H18-Página1!H$51-Página1!H$55+Página1!H$54 -> -13378067 | I24: =I18-Página1!I$51-Página1!I$55+Página1!I$54 -> -13469995 | J24: =SUM(D24:I24) -> -75860482
B26: LUCRO LÍQUIDO (R$/ano)
D27: =D9 -> 2026 | E27: =E9 -> 2027 | F27: =F9 -> 2028 | G27: =G9 -> 2029 | H27: =H9 -> 2030 | I27: =I9 -> 2031 | J27: Total 6 anos
B28: =B10 -> Otimista (100 km) | D28: =IF(D22>0,D22*(1-Página1!$D$58),D22) -> 777673.87 | E28: =IF(E22>0,E22*(1-Página1!$D$58),E22) -> -1540771 | F28: =IF(F22>0,F22*(1-Página1!$D$58),F22) -> -1462808.6 | G28: =IF(G22>0,G22*(1-Página1!$D$58),G22) -> -982670.31 | H28: =IF(H22>0,H22*(1-Página1!$D$58),H22) -> -498865.87 | I28: =IF(I22>0,I22*(1-Página1!$D$58),I22) -> -11230.254 | J28: =SUM(D28:I28) -> -3718672.2
B29: =B11 -> Razoável (200 km) | D29: =IF(D23>0,D23*(1-Página1!$D$58),D23) -> -4221706.2 | E29: =IF(E23>0,E23*(1-Página1!$D$58),E23) -> -7183771 | F29: =IF(F23>0,F23*(1-Página1!$D$58),F23) -> -7359743.6 | G29: =IF(G23>0,G23*(1-Página1!$D$58),G23) -> -7144967.4 | H29: =IF(H23>0,H23*(1-Página1!$D$58),H23) -> -6938466.3 | I29: =IF(I23>0,I23*(1-Página1!$D$58),I23) -> -6740612.7 | J29: =SUM(D29:I29) -> -39589267
B30: =B12 -> Pessimista (300 km) | D30: =IF(D24>0,D24*(1-Página1!$D$58),D24) -> -9621706.2 | E30: =IF(E24>0,E24*(1-Página1!$D$58),E24) -> -12826771 | F30: =IF(F24>0,F24*(1-Página1!$D$58),F24) -> -13256679 | G30: =IF(G24>0,G24*(1-Página1!$D$58),G24) -> -13307264 | H30: =IF(H24>0,H24*(1-Página1!$D$58),H24) -> -13378067 | I30: =IF(I24>0,I24*(1-Página1!$D$58),I24) -> -13469995 | J30: =SUM(D30:I30) -> -75860482
B32: Leitura
B33: Com frete pago pelo vendedor a R$ 0,45/t·km, só o cenário de ~100 km se sustenta (EBITDA positivo, mas próximo do zero após depreciação e juros).
B34: A partir de 200 km o frete supera a margem e o resultado fica negativo — existe um raio máximo econômico de entrega.
B35: Para vender mais longe: repassar o frete ao cliente (FOB), elevar o preço, ou baixar o custo de frete (R$/t·km).

Sheet Fluxo de Caixa
B1: FLUXO DE CAIXA & VIABILIDADE — SoloBom
B2: Cenário selecionado | C2: Entrada | D2: Razoável | E2: Distância | F2: =INDEX(Cenários!$D$4:$D$6,MATCH($D$2,Cenários!$B$4:$B$6,0)) -> 200 | G2: km | H2: Fonte | I2: Cenários!B4:D6
C3: Unidade | D3: =Página1!D2 -> 2026 | E3: =Página1!E2 -> 2027 | F3: =Página1!F2 -> 2028 | G3: =Página1!G2 -> 2029 | H3: =Página1!H2 -> 2030 | I3: =Página1!I2 -> 2031
B4: OPEX (custos + despesas operacionais)
B5: Custos Variáveis | C5: R$ | D5: =Página1!D22-Página1!D29+INDEX(Cenários!D$10:D$12,MATCH($D$2,Cenários!$B$4:$B$6,0)) -> 44288906 | E5: =Página1!E22-Página1!E29+INDEX(Cenários!E$10:E$12,MATCH($D$2,Cenários!$B$4:$B$6,0)) -> 46281907 | F5: =Página1!F22-Página1!F29+INDEX(Cenários!F$10:F$12,MATCH($D$2,Cenários!$B$4:$B$6,0)) -> 48364593 | G5: =Página1!G22-Página1!G29+INDEX(Cenários!G$10:G$12,MATCH($D$2,Cenários!$B$4:$B$6,0)) -> 50541000 | H5: =Página1!H22-Página1!H29+INDEX(Cenários!H$10:H$12,MATCH($D$2,Cenários!$B$4:$B$6,0)) -> 52815345 | I5: =Página1!I22-Página1!I29+INDEX(Cenários!I$10:I$12,MATCH($D$2,Cenários!$B$4:$B$6,0)) -> 55192035
B6: Custos Fixos | C6: R$ | D6: =Página1!D33 -> 2207600 | E6: =Página1!E33 -> 2285360 | F6: =Página1!F33 -> 2366619.2 | G6: =Página1!G33 -> 2451535.1 | H6: =Página1!H33 -> 2540272.1 | I6: =Página1!I33 -> 2633002.4
B7: Despesas administrativas | C7: R$ | D7: =Página1!D46 -> 360000 | E7: =Página1!E46 -> 376200 | F7: =Página1!F46 -> 393129 | G7: =Página1!G46 -> 410819.8 | H7: =Página1!H46 -> 429306.7 | I7: =Página1!I46 -> 448625.5
B8: OPEX Total | C8: R$ | D8: =D5+D6+D7 -> 46856506 | E8: =E5+E6+E7 -> 48943467 | F8: =F5+F6+F7 -> 51124341 | G8: =G5+G6+G7 -> 53403354 | H8: =H5+H6+H7 -> 55784923 | I8: =I5+I6+I7 -> 58273663
B9: OPEX por tonelada vendida | C9: R$/t | D9: =D8/Página1!D14 -> 390.47089 | E9: =E8/Página1!E14 -> 407.86223 | F9: =F8/Página1!F14 -> 426.03618 | G9: =G8/Página1!G14 -> 445.02795 | H9: =H8/Página1!H14 -> 464.87436 | I9: =I8/Página1!I14 -> 485.61386
B11: Lucro Líquido | C11: R$ | D11: =INDEX(Cenários!D$28:D$30,MATCH($D$2,Cenários!$B$4:$B$6,0)) -> -4221706.2 | E11: =INDEX(Cenários!E$28:E$30,MATCH($D$2,Cenários!$B$4:$B$6,0)) -> -7183771 | F11: =INDEX(Cenários!F$28:F$30,MATCH($D$2,Cenários!$B$4:$B$6,0)) -> -7359743.6 | G11: =INDEX(Cenários!G$28:G$30,MATCH($D$2,Cenários!$B$4:$B$6,0)) -> -7144967.4 | H11: =INDEX(Cenários!H$28:H$30,MATCH($D$2,Cenários!$B$4:$B$6,0)) -> -6938466.3 | I11: =INDEX(Cenários!I$28:I$30,MATCH($D$2,Cenários!$B$4:$B$6,0)) -> -6740612.7
B12: (+) Depreciação e Amortização | C12: R$ | D12: =CAPEX!D10 -> 0 | E12: =CAPEX!E10 -> 1199000 | F12: =CAPEX!F10 -> 1199000 | G12: =CAPEX!G10 -> 1199000 | H12: =CAPEX!H10 -> 1199000 | I12: =CAPEX!I10 -> 1199000
B13: (−) CAPEX (investimento) | C13: R$ | D13: =-CAPEX!D9 -> -11990000 | E13: =-CAPEX!E9 -> 0 | F13: =-CAPEX!F9 -> 0 | G13: =-CAPEX!G9 -> 0 | H13: =-CAPEX!H9 -> 0 | I13: =-CAPEX!I9 -> 0
B14: Fluxo de Caixa Livre | C14: R$ | D14: =D11+D12+D13 -> -16211706 | E14: =E11+E12+E13 -> -5984771 | F14: =F11+F12+F13 -> -6160743.6 | G14: =G11+G12+G13 -> -5945967.4 | H14: =H11+H12+H13 -> -5739466.3 | I14: =I11+I12+I13 -> -5541612.7
B15: Fator de desconto | C15: x | D15: =1/(1+$D$21)^(D$3-$D$3) -> 1 | E15: =1/(1+$D$21)^(E$3-$D$3) -> 0.89285714 | F15: =1/(1+$D$21)^(F$3-$D$3) -> 0.79719388 | G15: =1/(1+$D$21)^(G$3-$D$3) -> 0.71178025 | H15: =1/(1+$D$21)^(H$3-$D$3) -> 0.63551808 | I15: =1/(1+$D$21)^(I$3-$D$3) -> 0.56742686
B16: FC Livre Descontado | C16: R$ | D16: =D14*D15 -> -16211706 | E16: =E14*E15 -> -5343545.6 | F16: =F14*F15 -> -4911307.1 | G16: =G14*G15 -> -4232222.1 | H16: =H14*H15 -> -3647534.6 | I16: =I14*I15 -> -3144459.9
B17: FC Livre Acumulado | C17: R$ | D17: =D14 -> -16211706 | E17: =D17+E14 -> -22196477 | F17: =E17+F14 -> -28357221 | G17: =F17+G14 -> -34303188 | H17: =G17+H14 -> -40042655 | I17: =H17+I14 -> -45584267
B18: FC Descontado Acumulado | C18: R$ | D18: =D16 -> -16211706 | E18: =D18+E16 -> -21555252 | F18: =E18+F16 -> -26466559 | G18: =F18+G16 -> -30698781 | H18: =G18+H16 -> -34346316 | I18: =H18+I16 -> -37490775
B20: INDICADORES DE VIABILIDADE | C20: Unidade
B21: TMA (taxa de desconto) | C21: % aa | D21: 0.12
B22: Investimento (CAPEX) | C22: R$ | D22: =CAPEX!D3 -> 11990000
B23: VPL @ TMA | C23: R$ | D23: =SUM(D16:I16) -> -37490775
B24: TIR | C24: % | D24: =IFERROR(IRR(D14:I14),"n/d") -> n/d
B25: ROI (operação 2026-2030) | C25: % | D25: =(SUM(E14:I14)-D22)/D22 -> -3.4497549
B26: Payback simples | C26: anos | D26: {=IFERROR(COUNTIF(D17:I17,"<0")+(-INDEX(D17:I17,COUNTIF(D17:I17,"<0"))/INDEX(D14:I14,COUNTIF(D17:I17,"<0")+1)),"> horizonte")} -> > horizonte
B27: Payback descontado | C27: anos | D27: {=IFERROR(COUNTIF(D18:I18,"<0")+(-INDEX(D18:I18,COUNTIF(D18:I18,"<0"))/INDEX(D16:I16,COUNTIF(D18:I18,"<0")+1)),"> horizonte")} -> > horizonte
