Workbook

Sheet Premissas
A1: PREMISSAS — Secador de Esterco | PVA (Primavera) + Campanha | B1: PREMISSAS & DRE OPERACIONAL — Secador de Esterco | Itanhandu-MG
C2: Unidade | D2: 2026 | E2: =D2+1 -> 2027 | F2: =E2+1 -> 2028 | G2: =F2+1 -> 2029 | H2: =G2+1 -> 2030 | I2: =H2+1 -> 2031
B3: 1. PREMISSAS (inputs em amarelo)
B4: Inflação | C4: % aa | D4: 0.045 | E4: =D4 -> 0.045 | F4: =E4 -> 0.045 | G4: =F4 -> 0.045 | H4: =G4 -> 0.045 | I4: =H4 -> 0.045
B5: Esterco úmido — PVA (Primavera) | C5: t/dia | D5: 550 | E5: =D5 -> 550 | F5: =E5 -> 550 | G5: =F5 -> 550 | H5: =G5 -> 550 | I5: =H5 -> 550
B6: Esterco úmido — Campanha | C6: t/dia | D6: 440 | E6: =D6 -> 440 | F6: =E6 -> 440 | G6: =F6 -> 440 | H6: =G6 -> 440 | I6: =H6 -> 440
B7: Dias de operação/ano | C7: dias | D7: 365 | E7: =D7 -> 365 | F7: =E7 -> 365 | G7: =F7 -> 365 | H7: =G7 -> 365 | I7: =H7 -> 365
B8: Umidade inicial | C8: % | D8: 0.7 | E8: =D8 -> 0.7 | F8: =E8 -> 0.7 | G8: =F8 -> 0.7 | H8: =G8 -> 0.7 | I8: =H8 -> 0.7
B9: Umidade final (pós-secador) | C9: % | D9: 0.2 | E9: =D9 -> 0.2 | F9: =E9 -> 0.2 | G9: =F9 -> 0.2 | H9: =G9 -> 0.2 | I9: =H9 -> 0.2
B10: Volume de venda esperado | C10: t/ano | D10: 120000 | E10: =D10 -> 120000 | F10: =E10 -> 120000 | G10: =F10 -> 120000 | H10: =G10 -> 120000 | I10: =H10 -> 120000
B11: Preço do composto (2025) | C11: R$/t | D11: 360 | E11: =D11*(1+E$4) -> 376.2 | F11: =E11*(1+F$4) -> 393.129 | G11: =F11*(1+G$4) -> 410.8198 | H11: =G11*(1+H$4) -> 429.3067 | I11: =H11*(1+I$4) -> 448.6255
B12: Carga tributária s/ vendas | C12: % | D12: 0.08 | E12: =D12 -> 0.08 | F12: =E12 -> 0.08 | G12: =F12 -> 0.08 | H12: =G12 -> 0.08 | I12: =H12 -> 0.08
B13: Custo de energia (por t de água evaporada) | C13: R$/t água | D13: 117 | E13: =D13*(1+E$4) -> 122.265 | F13: =E13*(1+F$4) -> 127.76692 | G13: =F13*(1+G$4) -> 133.51644 | H13: =G13*(1+H$4) -> 139.52468 | I13: =H13*(1+I$4) -> 145.80329
B14: Custo aditivos | C14: R$/t seco | D14: 30 | E14: =D14*(1+E$4) -> 31.35 | F14: =E14*(1+F$4) -> 32.76075 | G14: =F14*(1+G$4) -> 34.234984 | H14: =G14*(1+H$4) -> 35.775558 | I14: =H14*(1+I$4) -> 37.385458
B15: Custo embalagem/ensaque | C15: R$/t vend. | D15: 25 | E15: =D15*(1+E$4) -> 26.125 | F15: =E15*(1+F$4) -> 27.300625 | G15: =F15*(1+G$4) -> 28.529153 | H15: =G15*(1+H$4) -> 29.812965 | I15: =H15*(1+I$4) -> 31.154548
B16: Operadores (planta industrial, turnos) | C16: # | D16: 20 | E16: =D16 -> 20 | F16: =E16 -> 20 | G16: =F16 -> 20 | H16: =G16 -> 20 | I16: =H16 -> 20
B17: Salário mensal/operador | C17: R$ | D17: 4000 | E17: =D17*(1+E$4) -> 4180 | F17: =E17*(1+F$4) -> 4368.1 | G17: =F17*(1+G$4) -> 4564.6645 | H17: =G17*(1+H$4) -> 4770.0744 | I17: =H17*(1+I$4) -> 4984.7278
B18: Encargos s/ folha | C18: % | D18: 0.8 | E18: =D18 -> 0.8 | F18: =E18 -> 0.8 | G18: =F18 -> 0.8 | H18: =G18 -> 0.8 | I18: =H18 -> 0.8
B19: Manutenção (% do equipamento) | C19: % | D19: 0.04 | E19: =D19 -> 0.04 | F19: =E19 -> 0.04 | G19: =F19 -> 0.04 | H19: =G19 -> 0.04 | I19: =H19 -> 0.04
B20: Frete | C20: R$/t·km | D20: 0.45 | E20: =D20*(1+E$4) -> 0.47025 | F20: =E20*(1+F$4) -> 0.49141125 | G20: =F20*(1+G$4) -> 0.51352476 | H20: =G20*(1+H$4) -> 0.53663337 | I20: =H20*(1+I$4) -> 0.56078187
B21: Distância média | C21: km | D21: 0 | E21: =D21 -> 0 | F21: =E21 -> 0 | G21: =F21 -> 0 | H21: =G21 -> 0 | I21: =H21 -> 0
B22: Fração descartada (entressafra) | C22: % | D22: 0 | E22: =D22 -> 0 | F22: =E22 -> 0 | G22: =F22 -> 0 | H22: =G22 -> 0 | I22: =H22 -> 0
B23: Penalidade descarte + doação | C23: R$/t | D23: 15 | E23: =D23*(1+E$4) -> 15.675 | F23: =E23*(1+F$4) -> 16.380375 | G23: =F23*(1+G$4) -> 17.117492 | H23: =G23*(1+H$4) -> 17.887779 | I23: =H23*(1+I$4) -> 18.692729
B24: Despesas administrativas | C24: R$/mês | D24: 30000 | E24: =D24*(1+E$4) -> 31350 | F24: =E24*(1+F$4) -> 32760.75 | G24: =F24*(1+G$4) -> 34234.984 | H24: =G24*(1+H$4) -> 35775.558 | I24: =H24*(1+I$4) -> 37385.458
B25: Alíquota IRPJ/CSLL | C25: % | D25: 0.34 | E25: =D25 -> 0.34 | F25: =E25 -> 0.34 | G25: =F25 -> 0.34 | H25: =G25 -> 0.34 | I25: =H25 -> 0.34
B26: 2. VOLUMES (calculado)
B27: Esterco úmido gerado | C27: t/ano | D27: =(D5+D6)*D7 -> 361350 | E27: =(E5+E6)*E7 -> 361350 | F27: =(F5+F6)*F7 -> 361350 | G27: =(G5+G6)*G7 -> 361350 | H27: =(H5+H6)*H7 -> 361350 | I27: =(I5+I6)*I7 -> 361350
B28: Fator massa seca | C28: x | D28: =(1-D8)/(1-D9) -> 0.375 | E28: =(1-E8)/(1-E9) -> 0.375 | F28: =(1-F8)/(1-F9) -> 0.375 | G28: =(1-G8)/(1-G9) -> 0.375 | H28: =(1-H8)/(1-H9) -> 0.375 | I28: =(1-I8)/(1-I9) -> 0.375
B29: Composto seco produzido | C29: t/ano | D29: =D27*D28 -> 135506.25 | E29: =E27*E28 -> 135506.25 | F29: =F27*F28 -> 135506.25 | G29: =G27*G28 -> 135506.25 | H29: =H27*H28 -> 135506.25 | I29: =I27*I28 -> 135506.25
B30: Composto vendido | C30: t/ano | D30: =MIN(D29,D10) -> 120000 | E30: =MIN(E29,E10) -> 120000 | F30: =MIN(F29,F10) -> 120000 | G30: =MIN(G29,G10) -> 120000 | H30: =MIN(H29,H10) -> 120000 | I30: =MIN(I29,I10) -> 120000
B31: Água removida | C31: t/ano | D31: =D27-D29 -> 225843.75 | E31: =E27-E29 -> 225843.75 | F31: =F27-F29 -> 225843.75 | G31: =G27-G29 -> 225843.75 | H31: =H27-H29 -> 225843.75 | I31: =I27-I29 -> 225843.75
B33: 3. DRE OPERACIONAL
B34: Receita Bruta | C34: R$ | D34: =D30*D11 -> 43200000 | E34: =E30*E11 -> 45144000 | F34: =F30*F11 -> 47175480 | G34: =G30*G11 -> 49298377 | H34: =H30*H11 -> 51516804 | I34: =I30*I11 -> 53835060
B35: (−) Impostos sobre vendas | C35: R$ | D35: =D34*D12 -> 3456000 | E35: =E34*E12 -> 3611520 | F35: =F34*F12 -> 3774038.4 | G35: =G34*G12 -> 3943870.1 | H35: =H34*H12 -> 4121344.3 | I35: =I34*I12 -> 4306804.8
B36: Receita Líquida | C36: R$ | D36: =D34-D35 -> 39744000 | E36: =E34-E35 -> 41532480 | F36: =F34-F35 -> 43401442 | G36: =G34-G35 -> 45354506 | H36: =H34-H35 -> 47395459 | I36: =I34-I35 -> 49528255
B37: (−) Energia (cavaco/biomassa) | C37: R$ | D37: =D13*D31 -> 26423719 | E37: =E13*E31 -> 27612786 | F37: =F13*F31 -> 28855361 | G37: =G13*G31 -> 30153853 | H37: =H13*H31 -> 31510776 | I37: =I13*I31 -> 32928761
B38: (−) Aditivos | C38: R$ | D38: =D14*D29 -> 4065187.5 | E38: =E14*E29 -> 4248120.9 | F38: =F14*F29 -> 4439286.4 | G38: =G14*G29 -> 4639054.3 | H38: =H14*H29 -> 4847811.7 | I38: =I14*I29 -> 5065963.2
B39: (−) Embalagem/ensaque | C39: R$ | D39: =D15*D30 -> 3000000 | E39: =E15*E30 -> 3135000 | F39: =F15*F30 -> 3276075 | G39: =G15*G30 -> 3423498.4 | H39: =H15*H30 -> 3577555.8 | I39: =I15*I30 -> 3738545.8
B40: Custos Variáveis | C40: R$ | D40: =D37+D38+D39 -> 33488906 | E40: =E37+E38+E39 -> 34995907 | F40: =F37+F38+F39 -> 36570723 | G40: =G37+G38+G39 -> 38216405 | H40: =H37+H38+H39 -> 39936144 | I40: =I37+I38+I39 -> 41733270
B41: (−) Mão de obra | C41: R$ | D41: =D16*D17*12*(1+D18) -> 1728000 | E41: =E16*E17*12*(1+E18) -> 1805760 | F41: =F16*F17*12*(1+F18) -> 1887019.2 | G41: =G16*G17*12*(1+G18) -> 1971935.1 | H41: =H16*H17*12*(1+H18) -> 2060672.1 | I41: =I16*I17*12*(1+I18) -> 2153402.4
...

Sheet DRE
B1: DRE — Secador de Esterco | PVA (Primavera) + Campanha
C2: Unidade | D2: =Premissas!D2 -> 2026 | E2: =D2+1 -> 2027 | F2: =E2+1 -> 2028 | G2: =F2+1 -> 2029 | H2: =G2+1 -> 2030 | I2: =H2+1 -> 2031
B3: Receita Bruta | C3: R$ | D3: =Premissas!D34 -> 43200000 | E3: =Premissas!E34 -> 45144000 | F3: =Premissas!F34 -> 47175480 | G3: =Premissas!G34 -> 49298377 | H3: =Premissas!H34 -> 51516804 | I3: =Premissas!I34 -> 53835060
B4: yoy | C4: % | E4: =E3/D3-1 -> 0.045 | F4: =F3/E3-1 -> 0.045 | G4: =G3/F3-1 -> 0.045 | H4: =H3/G3-1 -> 0.045 | I4: =I3/H3-1 -> 0.045
B5: (−) Impostos sobre vendas | C5: R$ | D5: =Premissas!D35 -> 3456000 | E5: =Premissas!E35 -> 3611520 | F5: =Premissas!F35 -> 3774038.4 | G5: =Premissas!G35 -> 3943870.1 | H5: =Premissas!H35 -> 4121344.3 | I5: =Premissas!I35 -> 4306804.8
B6: Receita Líquida | C6: R$ | D6: =Premissas!D36 -> 39744000 | E6: =Premissas!E36 -> 41532480 | F6: =Premissas!F36 -> 43401442 | G6: =Premissas!G36 -> 45354506 | H6: =Premissas!H36 -> 47395459 | I6: =Premissas!I36 -> 49528255
B7: (−) Custos Variáveis | C7: R$ | D7: =Premissas!D40 -> 33488906 | E7: =Premissas!E40 -> 34995907 | F7: =Premissas!F40 -> 36570723 | G7: =Premissas!G40 -> 38216405 | H7: =Premissas!H40 -> 39936144 | I7: =Premissas!I40 -> 41733270
B8: (−) Custos Fixos | C8: R$ | D8: =Premissas!D43 -> 2328000 | E8: =Premissas!E43 -> 2405760 | F8: =Premissas!F43 -> 2487019.2 | G8: =Premissas!G43 -> 2571935.1 | H8: =Premissas!H43 -> 2660672.1 | I8: =Premissas!I43 -> 2753402.4
B9: Lucro Bruto | C9: R$ | D9: =Premissas!D44 -> 3927093.8 | E9: =Premissas!E44 -> 4130813 | F9: =Premissas!F44 -> 4343699.6 | G9: =Premissas!G44 -> 4566166 | H9: =Premissas!H44 -> 4798643.5 | I9: =Premissas!I44 -> 5041582.5
B10: Margem Bruta | C10: % | D10: =D9/D6 -> 0.098809726 | E10: =E9/E6 -> 0.09945982 | F10: =F9/F6 -> 0.10008192 | G10: =G9/G6 -> 0.10067723 | H10: =H9/H6 -> 0.1012469 | I10: =I9/I6 -> 0.10179205
B11: (+) Economias operacionais | C11: R$ | D11: =Premissas!D48 -> 0 | E11: =Premissas!E48 -> 0 | F11: =Premissas!F48 -> 0 | G11: =Premissas!G48 -> 0 | H11: =Premissas!H48 -> 0 | I11: =Premissas!I48 -> 0
B12: (−) Despesas administrativas | C12: R$ | D12: =Premissas!D49 -> 360000 | E12: =Premissas!E49 -> 376200 | F12: =Premissas!F49 -> 393129 | G12: =Premissas!G49 -> 410819.8 | H12: =Premissas!H49 -> 429306.7 | I12: =Premissas!I49 -> 448625.5
B13: EBITDA | C13: R$ | D13: =Premissas!D50 -> 3567093.8 | E13: =Premissas!E50 -> 3754613 | F13: =Premissas!F50 -> 3950570.6 | G13: =Premissas!G50 -> 4155346.2 | H13: =Premissas!H50 -> 4369336.8 | I13: =Premissas!I50 -> 4592957
B14: Margem EBITDA | C14: % | D14: =D13/D6 -> 0.089751755 | E14: =E13/E6 -> 0.090401849 | F14: =F13/F6 -> 0.091023948 | G14: =G13/G6 -> 0.091619258 | H14: =H13/H6 -> 0.092188933 | I14: =I13/I6 -> 0.092734076
B15: (−) Depreciação e Amortização | C15: R$ | D15: =CAPEX!D16 -> 0 | E15: =CAPEX!E16 -> 2500000 | F15: =CAPEX!F16 -> 2500000 | G15: =CAPEX!G16 -> 2500000 | H15: =CAPEX!H16 -> 2500000 | I15: =CAPEX!I16 -> 2500000
B16: EBIT | C16: R$ | D16: =Premissas!D53 -> 3567093.8 | E16: =Premissas!E53 -> 1254613 | F16: =Premissas!F53 -> 1450570.6 | G16: =Premissas!G53 -> 1655346.2 | H16: =Premissas!H53 -> 1869336.8 | I16: =Premissas!I53 -> 2092957
B17: Margem EBIT | C17: % | D17: =D16/D6 -> 0.089751755 | E17: =E16/E6 -> 0.030207995 | F17: =F16/F6 -> 0.033422174 | G17: =G16/G6 -> 0.036497944 | H17: =H16/H6 -> 0.039441264 | I17: =I16/I6 -> 0.042257838
B18: Resultado financeiro | C18: R$ | D18: =Premissas!D55 -> 0 | E18: =Premissas!E55 -> 0 | F18: =Premissas!F55 -> 0 | G18: =Premissas!G55 -> 0 | H18: =Premissas!H55 -> 0 | I18: =Premissas!I55 -> 0
B19: LAIR | C19: R$ | D19: =Premissas!D56 -> 3567093.8 | E19: =Premissas!E56 -> 1254613 | F19: =Premissas!F56 -> 1450570.6 | G19: =Premissas!G56 -> 1655346.2 | H19: =Premissas!H56 -> 1869336.8 | I19: =Premissas!I56 -> 2092957
B20: (−) IRPJ/CSLL | C20: R$ | D20: =Premissas!D57 -> 1212811.9 | E20: =Premissas!E57 -> 426568.41 | F20: =Premissas!F57 -> 493193.99 | G20: =Premissas!G57 -> 562817.72 | H20: =Premissas!H57 -> 635574.51 | I20: =Premissas!I57 -> 711605.37
B21: Lucro Líquido | C21: R$ | D21: =Premissas!D58 -> 2354281.9 | E21: =Premissas!E58 -> 828044.56 | F21: =Premissas!F58 -> 957376.56 | G21: =Premissas!G58 -> 1092528.5 | H21: =Premissas!H58 -> 1233762.3 | I21: =Premissas!I58 -> 1381351.6
B22: Margem Líquida | C22: % | D22: =D21/D6 -> 0.059236158 | E22: =E21/E6 -> 0.019937277 | F22: =F21/F6 -> 0.022058635 | G22: =G21/G6 -> 0.024088643 | H22: =H21/H6 -> 0.026031234 | I22: =I21/I6 -> 0.027890173

Sheet CAPEX
B1: CAPEX — Secador Industrial de Esterco
C2: Unidade | D2: 2026 | E2: =D2+1 -> 2027 | F2: =E2+1 -> 2028 | G2: =F2+1 -> 2029 | H2: =G2+1 -> 2030 | I2: =H2+1 -> 2031
B3: Secador (5 linhas a biomassa — ver dimensionamento) | C3: R$ | D3: =D35 -> 15000000
B4: Obra civil, galpão e instalação | C4: R$ | D4: 4000000
B5: Licenças ambientais | C5: R$ | D5: 500000
B6: Equip. auxiliares (aditivação, granulação, ensacadora) | C6: R$ | D6: 3000000
B7: Capital de giro inicial | C7: R$ | D7: 2500000
B8: Contingência (10%) | C8: R$ | D8: =0.1*SUM(D3:D7) -> 2500000
B9: CAPEX Total (investimento) | C9: R$ | D9: =SUM(D3:D8) -> 27500000
B10: Base deprecíavel (exclui capital de giro) | C10: R$ | D10: =D9-D7 -> 25000000
B11: Tempo de depreciação | C11: anos | D11: 10
B13: Roll-forward do imobilizado | C13: Unidade | D13: =D2 -> 2026 | E13: =E2 -> 2027 | F13: =F2 -> 2028 | G13: =G2 -> 2029 | H13: =H2 -> 2030 | I13: =I2 -> 2031 | J13: 2031 | K13: 2032 | L13: 2033 | M13: 2034 | N13: 2035
B14: Saldo Inicial | C14: R$ | D14: 0 | E14: =D17 -> 25000000 | F14: =E17 -> 22500000 | G14: =F17 -> 20000000 | H14: =G17 -> 17500000 | I14: =H17 -> 15000000 | J14: =I17 -> 12500000 | K14: =J17 -> 10000000 | L14: =K17 -> 7500000 | ... N14: =M17 -> 2500000
B15: Ativo depreciável (exclui capital de giro) | C15: R$ | D15: =D10 -> 25000000 | E15: 0 | F15: 0 | G15: 0 | H15: 0 | I15: 0 | J15: 0 | K15: 0 | L15: 0 | M15: 0 | N15: 0
B16: (−) Depreciação e Amortização | C16: R$ | D16: 0 | E16: =$D$10/$D$11 -> 2500000 | F16: =E16 -> 2500000 | G16: =F16 -> 2500000 | H16: =G16 -> 2500000 | I16: =H16 -> 2500000 | J16: =I16 -> 2500000 | K16: =J16 -> 2500000 | L16: =K16 -> 2500000 | M16: =L16 -> 2500000 | N16: =M16 -> 2500000
B17: Saldo Final | C17: R$ | D17: =D14+D15-D16 -> 25000000 | E17: =E14+E15-E16 -> 22500000 | F17: =F14+F15-F16 -> 20000000 | G17: =G14+G15-G16 -> 17500000 | H17: =H14+H15-H16 -> 15000000 | I17: =I14+I15-I16 -> 12500000 | J17: =J14+J15-J16 -> 10000000 | K17: =K14+K15-K16 -> 7500000 | ... N17: =N14+N15-N16 -> 0
B19: RECUPERAÇÃO DO INVESTIMENTO (payback)
C20: Unidade | D20: =D2 -> 2026 | E20: =E2 -> 2027 | F20: =F2 -> 2028 | G20: =G2 -> 2029 | H20: =H2 -> 2030 | I20: =I2 -> 2031
B21: FC Livre do projeto | C21: R$ | D21: ='Fluxo de Caixa'!D6 -> -27500000 | E21: ='Fluxo de Caixa'!E6 -> 3328044.6 | F21: ='Fluxo de Caixa'!F6 -> 3457376.6 | G21: ='Fluxo de Caixa'!G6 -> 3592528.5 | H21: ='Fluxo de Caixa'!H6 -> 3733762.3 | I21: ='Fluxo de Caixa'!I6 -> 3881351.6
B22: Caixa acumulado | C22: R$ | D22: ='Fluxo de Caixa'!D9 -> -27500000 | E22: ='Fluxo de Caixa'!E9 -> -24171955 | F22: ='Fluxo de Caixa'!F9 -> -20714579 | G22: ='Fluxo de Caixa'!G9 -> -17122050 | H22: ='Fluxo de Caixa'!H9 -> -13388288 | I22: ='Fluxo de Caixa'!I9 -> -9506936.5
B23: % do CAPEX recuperado | C23: % | D23: =MIN(1,('Fluxo de Caixa'!D9+$D$9)/$D$9) -> 0 | E23: =MIN(1,('Fluxo de Caixa'!E9+$D$9)/$D$9) -> 0.1210198 | F23: =MIN(1,('Fluxo de Caixa'!F9+$D$9)/$D$9) -> 0.24674259 | G23: =MIN(1,('Fluxo de Caixa'!G9+$D$9)/$D$9) -> 0.37737999 | H23: =MIN(1,('Fluxo de Caixa'!H9+$D$9)/$D$9) -> 0.51315316 | I23: =MIN(1,('Fluxo de Caixa'!I9+$D$9)/$D$9) -> 0.65429322
B25: Payback (anos de operação) | C25: anos | D25: ='Fluxo de Caixa'!D18 -> >6
B26: Investimento se paga no ano | C26: ano | D26: {=IFERROR(INDEX($D$20:$I$20,MATCH(TRUE,INDEX($D$22:$I$22>=0,0),0)),"> 2030")} -> > 2030
B28: DIMENSIONAMENTO DO SECADOR
B29: Esterco a processar | C29: t/ano | D29: =Premissas!D27 -> 361350
B30: Horas de operação/ano | C30: h | D30: 7000
B31: Vazão de esterco | C31: t/h | D31: =D29/D30 -> 51.621429
B32: Capacidade por linha | C32: t/h | D32: 12
B33: Nº de linhas (secadores) | C33: # | D33: =ROUNDUP(D31/D32,0) -> 5
B34: Custo por linha completa | C34: R$ | D34: 3000000
B35: Secadores (total) | C35: R$ | D35: =D33*D34 -> 15000000

Sheet Fluxo de Caixa
B1: FLUXO DE CAIXA & VALUATION — Secador de Esterco
B2: (2025 = construção/CAPEX; operação 2026–2030) | C2: Unidade | D2: =Premissas!D2 -> 2026 | E2: =D2+1 -> 2027 | F2: =E2+1 -> 2028 | G2: =F2+1 -> 2029 | H2: =G2+1 -> 2030 | I2: =H2+1 -> 2031
B3: Lucro Líquido | C3: R$ | D3: 0 | E3: =DRE!E21 -> 828044.56 | F3: =DRE!F21 -> 957376.56 | G3: =DRE!G21 -> 1092528.5 | H3: =DRE!H21 -> 1233762.3 | I3: =DRE!I21 -> 1381351.6
B4: (+) Depreciação e Amortização | C4: R$ | D4: 0 | E4: =DRE!E15 -> 2500000 | F4: =DRE!F15 -> 2500000 | G4: =DRE!G15 -> 2500000 | H4: =DRE!H15 -> 2500000 | I4: =DRE!I15 -> 2500000
B5: (−) CAPEX (investimento) | C5: R$ | D5: =-CAPEX!D9 -> -27500000 | E5: 0 | F5: 0 | G5: 0 | H5: 0 | I5: 0
B6: Fluxo de Caixa Livre | C6: R$ | D6: =D3+D4+D5 -> -27500000 | E6: =E3+E4+E5 -> 3328044.6 | F6: =F3+F4+F5 -> 3457376.6 | G6: =G3+G4+G5 -> 3592528.5 | H6: =H3+H4+H5 -> 3733762.3 | I6: =I3+I4+I5 -> 3881351.6
B7: Fator de desconto | C7: x | D7: =1/(1+$D$13)^(D2-$D$2) -> 1 | E7: =1/(1+$D$13)^(E2-$D$2) -> 0.89285714 | F7: =1/(1+$D$13)^(F2-$D$2) -> 0.79719388 | G7: =1/(1+$D$13)^(G2-$D$2) -> 0.71178025 | H7: =1/(1+$D$13)^(H2-$D$2) -> 0.63551808 | I7: =1/(1+$D$13)^(I2-$D$2) -> 0.56742686
B8: FC Livre Descontado | C8: R$ | D8: =D6*D7 -> -27500000 | E8: =E6*E7 -> 2971468.4 | F8: =F6*F7 -> 2756199.4 | G8: =G6*G7 -> 2557090.8 | H8: =H6*H7 -> 2372873.4 | I8: =I6*I7 -> 2202383.1
B9: FC Livre Acumulado | C9: R$ | D9: =D6 -> -27500000 | E9: =D9+E6 -> -24171955 | F9: =E9+F6 -> -20714579 | G9: =F9+G6 -> -17122050 | H9: =G9+H6 -> -13388288 | I9: =H9+I6 -> -9506936.5
B10: FC Descontado Acumulado | C10: R$ | D10: =D8 -> -27500000 | E10: =D10+E8 -> -24528532 | F10: =E10+F8 -> -21772332 | G10: =F10+G8 -> -19215241 | H10: =G10+H8 -> -16842368 | I10: =H10+I8 -> -14639985
B12: INDICADORES DE VIABILIDADE
B13: TMA (taxa de desconto) | C13: % aa | D13: 0.12
B14: Investimento (CAPEX) | C14: R$ | D14: =CAPEX!D9 -> 27500000
B15: VPL @ TMA | C15: R$ | D15: =SUM(D8:I8) -> -14639985
B16: TIR | C16: % | D16: =IRR(D6:I6) -> -0.12386935
B17: ROI (operação 5 anos) | C17: % | D17: =(SUM(E6:I6)-D14)/D14 -> -0.34570678
B18: Payback simples | C18: anos | D18: {=IFERROR((COUNTIF(D9:I9,"<0")-1)+(-INDEX(D9:I9,COUNTIF(D9:I9,"<0")))/INDEX(D6:I6,COUNTIF(D9:I9,"<0")+1),">6")} -> >6
B19: Payback descontado | C19: anos | D19: {=IFERROR((COUNTIF(D10:I10,"<0")-1)+(-INDEX(D10:I10,COUNTIF(D10:I10,"<0")))/INDEX(D8:I8,COUNTIF(D10:I10,"<0")+1),">6")} -> >6
